2020-12-02 08:57:02,163 |                  flt |    ERROR | Traceback (most recent call last):
  File "/usr/local/lib/python3.7/dist-packages/foliant/cli/make.py", line 100, in get_config
    config = Parser(project_path, config_file_name, self.logger, quiet).parse()
  File "/usr/local/lib/python3.7/dist-packages/foliant/config/base.py", line 37, in parse
    with open(self.config_path, encoding='utf8') as config_file:
FileNotFoundError: [Errno 2] No such file or directory: 'foliant.yml'

During handling of the above exception, another exception occurred:

Traceback (most recent call last):
  File "/usr/local/lib/python3.7/dist-packages/foliant/utils.py", line 158, in spinner
    yield
  File "/usr/local/lib/python3.7/dist-packages/foliant/cli/make.py", line 104, in get_config
    raise FileNotFoundError(f'{exception} not found')
FileNotFoundError: [Errno 2] No such file or directory: 'foliant.yml' not found

2020-12-02 08:57:02,163 |                  flt | CRITICAL | Config parsing failed.
